<?xml version='1.0'?>

<robot name="my_robot" xmlns:xacro="http://www.ros.org/wiki/xacro">
	<xacro:include filename="$(find my_robot)/urdf/carRobot.gazebo" />


	<link name="robot_footprint"></link>
	
	<joint name="robot_footprint_joint" type="fixed">
		<origin xyz="0 0 0" rpy="0 0 0" />
			<parent link="robot_footprint"/>
		<child link="chassis" />
	</joint>




<!-- WHEELS -->
	<link name='right_wheel_front'>
		<inertial>
			<origin xyz="0 0 0" rpy="0 1.5707 1.5707" />
			<mass value="5.0"/>
			<inertia
			  ixx="0.1" ixy="0" ixz="0"
			  iyy="0.1" iyz="0"
			  izz="0.1"
			  	/>
		</inertial>

		<collision>
			<origin xyz="0 0 0" rpy="0 1.5707 1.5707" />
			<geometry>
		   		<cylinder radius="0.1" length="0.05"/>
			</geometry>
		</collision>

		<visual>
			<origin xyz="0 0 0" rpy="0 1.5707 1.5707" />
			<geometry>
		   		<cylinder radius="0.1" length="0.05"/>
			</geometry>
		</visual>
	</link>

	<link name='left_wheel_front'>
		<inertial>
			<origin xyz="0 0 0" rpy="0 1.5707 1.5707" />
			<mass value="5.0"/>
			<inertia
			  ixx="0.1" ixy="0" ixz="0"
			  iyy="0.1" iyz="0"
			  izz="0.1"
			  	/>
		</inertial>

		<collision>
			<origin xyz="0 0 0" rpy="0 1.5707 1.5707" />
			<geometry>
		   		<cylinder radius="0.1" length="0.05"/>
			</geometry>
		</collision>

		<visual>
			<origin xyz="0 0 0" rpy="0 1.5707 1.5707" />
			<geometry>
		   		<cylinder radius="0.1" length="0.05"/>
			</geometry>
		</visual>
	</link>
<!--
	<link name='right_wheel_back'>
		<inertial>
			<origin xyz="0 0 0" rpy="0 1.5707 1.5707" />
			<mass value="5.0"/>
			<inertia
			  ixx="0.1" ixy="0" ixz="0"
			  iyy="0.1" iyz="0"
			  izz="0.1"
			  	/>
		</inertial>

		<collision>
			<origin xyz="0 0 0" rpy="0 1.5707 1.5707" />
			<geometry>
		   		<cylinder radius="0.1" length="0.05"/>
			</geometry>
		</collision>

		<visual>
			<origin xyz="0 0 0" rpy="0 1.5707 1.5707" />
			<geometry>
		   		<cylinder radius="0.1" length="0.05"/>
			</geometry>
		</visual>
	</link>

	<link name='left_wheel_back'>
		<inertial>
			<origin xyz="0 0 0" rpy="0 1.5707 1.5707" />
			<mass value="5.0"/>
			<inertia
			  ixx="0.1" ixy="0" ixz="0"
			  iyy="0.1" iyz="0"
			  izz="0.1"
			  	/>
		</inertial>

		<collision>
			<origin xyz="0 0 0" rpy="0 1.5707 1.5707" />
			<geometry>
		   		<cylinder radius="0.1" length="0.05"/>
			</geometry>
		</collision>

		<visual>
			<origin xyz="0 0 0" rpy="0 1.5707 1.5707" />
			<geometry>
		   		<cylinder radius="0.1" length="0.05"/>
			</geometry>
		</visual>
	</link>
-->



<!-- CASSIS -->  
	<link name='chassis'>
		<pose>0 0 0.1 0 0 0</pose>

		<inertial>
			<mass value="10.0"/>
			<origin xyz="0 0 0" rpy=" 0 0 0"/>
			<inertia
			  ixx="0.1" ixy="0" ixz="0"
			  iyy="0.1" iyz="0"
			  izz="0.1"
			/>
		</inertial>

		<collision name='collision'>
			<origin xyz="0 0 0" rpy=" 0 0 0"/> 
			<geometry>
			<box size=".6 .3 .1"/>
			</geometry>
		</collision>

		<visual name='chassis_visual'>
			<origin xyz="0 0 0" rpy=" 0 0 0"/>
			<geometry>
			<box size=".6 .3 .1"/>
			</geometry>
		</visual>
		
		<collision name='back_caster_collision'>
			<origin xyz="-0.2 0 -0.05" rpy=" 0 0 0"/>
			<geometry>
			<sphere radius="0.099"/>
			</geometry>
		</collision>

		<visual name='back_caster_visual'>
			<origin xyz="-0.2 0 -0.05" rpy=" 0 0 0"/>
			<geometry>
			<sphere radius="0.099"/>
			</geometry>
		</visual>

		<collision name='front_caster_collision'>
			<origin xyz="0.2 0 -0.05" rpy=" 0 0 0"/>
			<geometry>
			<sphere radius="0.099"/>
			</geometry>
		</collision>

		<visual name='front_caster_visual'>
			<origin xyz="0.2 0 -0.05" rpy=" 0 0 0"/>
			<geometry>
			<sphere radius="0.099"/>
			</geometry>
  		</visual>
	</link>



<!-- CAB -->	
	<link name='cab'>
		<pose>0 0 0.1 0 0 0</pose>
		<inertial>
			<mass value="3.0"/>
			<origin xyz="0 0 0" rpy=" 0 0 0"/>
			<inertia
			  ixx="0.1" ixy="0" ixz="0"
			  iyy="0.1" iyz="0"
			  izz="0.1"
			/>
		</inertial>
		<collision name='cab_collision'>
		  <origin xyz="0 0 0" rpy=" 0 0 0"/> 
		  <geometry>
			<box size=".3 .3 .15"/>
		  </geometry>
		</collision>
		<visual name='cab_visual'>
		  <origin xyz="0 0 0" rpy=" 0 0 0"/>
		  <geometry>
			<box size=".3 .3 .15"/>
		  </geometry>
		</visual>
	</link>
	
	<joint type="fixed" name="cab_chassis_joint">
		<origin xyz="0.0 0 0.12" rpy="0 0 0"/>
		<child link="cab"/>
		<parent link="chassis"/>
		<axis xyz="0 1 0" rpy="0 0 0"/>
	</joint>
	
	
	
<!-- Lidar Tower -->	
	<link name='LidarTower'>
		<pose>0 0 0.1 0 0 0</pose>
		<inertial>
			<mass value="1.0"/>
			<origin xyz="0 0 0" rpy=" 0 0 0"/>
			<inertia
			  ixx="0.1" ixy="0" ixz="0"
			  iyy="0.1" iyz="0"
			  izz="0.1"
			/>
		</inertial>
		<collision name='LidarTower_collision'>
		  <origin xyz="0 0 0" rpy=" 0 0 0"/> 
		  <geometry>
			<cylinder radius="0.05" length="0.12"/>
		  </geometry>
		</collision>
		<visual name='LidarTower_visual'>
		  <origin xyz="0 0 0" rpy=" 0 0 0"/>
		  <geometry>
			<cylinder radius="0.05" length="0.125"/>
		  </geometry>
		</visual>
	</link>
	
	<joint type="fixed" name="cab_LidarTower_joint">
		<origin xyz="0.0 0 0.125" rpy="0 0 0"/>
		<child link="LidarTower"/>
		<parent link="cab"/>
		<axis xyz="0 1 0" rpy="0 0 0"/>
	</joint>
	

	<joint type="continuous" name="left_wheel_front_hinge">
		<origin xyz="0.0 0.18 -0.05" rpy="0 0 0"/>
		<child link="left_wheel_front"/>
		<parent link="chassis"/>
		<axis xyz="0 1 0" rpy="0 0 0"/>
		<limit effort="10000" velocity="1000"/>
		<dynamics damping="1.0" friction="1.0"/>
	</joint>

	<joint type="continuous" name="right_wheel_front_hinge">
		<origin xyz="0.0 -0.18 -0.05" rpy="0 0 0"/>
		<child link="right_wheel_front"/>
		<parent link="chassis"/>
		<axis xyz="0 1 0" rpy="0 0 0"/>
		<limit effort="10000" velocity="1000"/>
		<dynamics damping="1.0" friction="1.0"/>
	</joint>
<!--
	<joint type="continuous" name="left_wheel_back_hinge">
		<origin xyz="-0.2 0.18 -0.05" rpy="0 0 0"/>
		<child link="left_wheel_back"/>
		<parent link="chassis"/>
		<axis xyz="0 1 0" rpy="0 0 0"/>
	</joint>

	<joint type="continuous" name="right_wheel_back_hinge">
		<origin xyz="-0.2 -0.18 -0.05" rpy="0 0 0"/>
		<child link="right_wheel_back"/>
		<parent link="chassis"/>
		<axis xyz="0 1 0" rpy="0 0 0"/>
	</joint>
-->



	<link name='camera_link'>
		<inertial>
			<mass value="0.1"/>
				<origin xyz="0.0 0 0" rpy=" 0 0 0"/>
				<inertia
			 		ixx="1e-6" ixy="0" ixz="0"
			  		iyy="1e-6" iyz="0"
			  		izz="1e-6"
				/>
		</inertial>

		<visual>
			<origin xyz="0 0 0" rpy="0 0 0"/>
			<geometry>
				<box size="0.05 0.05 0.05"/>
			</geometry>
		</visual>

			<collision>
			<origin xyz="0 0 0" rpy="0 0 0"/>
			<geometry>
				<box size="0.05 0.05 0.05"/>
			</geometry>
			</collision>
	</link>

	<joint type="fixed" name="camera_joint">
		<origin xyz="0.175 0 0.05" rpy="0 0 0"/>
		<child link="camera_link"/>
		<parent link="cab"/>
		<axis xyz="0 1 0" rpy="0 0 0"/>
	</joint>
    
    <link name="camera_link_optical">
    </link>
    
    <joint name="camera_optical_joint" type="fixed">
    <origin xyz="0 0 0" rpy="-1.5707 0 -1.5707"/>
    <parent link="camera_link"/>
    <child link="camera_link_optical"/>
    </joint>


    

	<link name="hokuyo">
		<inertial>
			<mass value="1e-5"/>
				<origin xyz="0 0 0" rpy=" 0 0 0"/>
				<inertia
			 		ixx="1e-6" ixy="0" ixz="0"
			  		iyy="1e-6" iyz="0"
			  		izz="1e-6"
				/>
		</inertial>

		<visual>
			<origin xyz="0 0 0" rpy="0 0 0"/>
			<geometry>
				<mesh filename="package://my_robot/meshes/hokuyo.dae"/>
			</geometry>
		</visual>

		<collision>
			<origin xyz="0 0 0" rpy="0 0 0"/>
			<geometry>
				<mesh filename="package://my_robot/meshes/hokuyo.dae"/>
			</geometry>
		</collision>

	</link>

	<joint type="fixed" name="hokuyo_joint">
		<origin xyz="0 0 0.1" rpy="0 0 0"/>
		<child link="hokuyo"/>
		<parent link="LidarTower"/>
		<axis xyz="0 1 0" rpy="0 0 0"/>
	</joint>

	<gazebo reference="left_wheel_front">
		<material>Gazebo/Green</material>
	</gazebo>

	<gazebo reference="right_wheel_front">
		<material>Gazebo/Green</material>
	</gazebo>
<!--
	<gazebo reference="left_wheel_back">
		<material>Gazebo/Green</material>
	</gazebo>

	<gazebo reference="right_wheel_back">
		<material>Gazebo/Green</material>
	</gazebo>
-->
	<gazebo reference="chassis">
		<material>Gazebo/Blue</material>
	</gazebo>
	
	<gazebo reference="cab">
		<material>Gazebo/Blue</material>
	</gazebo>
	
	<gazebo reference="LidarTower">
		<material>Gazebo/Blue</material>
	</gazebo>

	<gazebo reference="camera">
		<material>Gazebo/Red</material>
	</gazebo>

</robot>
